Workbook

Sheet Q1 Direct Lending
A1: Q1: Direct Mortgage Lending – Monthly Cash Flows & Expected Return
A3: ASSUMPTIONS
A4: Loan Amount ($) | B4: 5800000 | C4: Case: UPL treasury proceeds
A5: Coupon Rate (annual) | B5: 0.08 | C5: Exhibit 6: 8.0% midpoint for 60-69% LTV
A6: Amortization (months) | B6: 360 | C6: Exhibit 6: 30-year amortization
A7: Loan Term (years) | B7: 5 | C7: Exhibit 6: match CMBS 5-yr term; consistent with friend
A8: Origination Fee (bps) | B8: 100 | C8: Exhibit 6
A9: P(Default) – Ba, 5yr | B9: 0.0702 | C9: Exhibit 15: 5-yr cumulative Ba loss rate
A10: Recovery Rate | B10: 0.4
A13: DERIVED CALCULATIONS
A14: Monthly Interest Rate | B14: =B5/12 -> 0.0066666667
A15: Monthly Payment ($) | B15: =PMT(B5/12,B6,-B4) -> 42558.345
A16: Origination Fee ($) | B16: =B4*B8/10000 -> 58000
A17: Net Outlay ($) | B17: =B4-B16 -> 5742000
A18: Balloon Balance ($) | B18: =ABS(FV(B5/12,B7*12,-B15,B4)) -> 5514051.7
A19: Total Final Payment ($) | B19: =B15+B18 -> 5556610
A21: PROMISED MONTHLY CASH FLOW SCHEDULE
A22: Month | B22: Description | C22: Payment ($) | D22: Balloon ($) | E22: Net Cash Flow ($)
A23: 0 | B23: Origination (net outlay) | C23: - | D23: - | E23: =-B17 -> -5742000
A24: 1 | B24: Monthly Payment | C24: =$B$15 -> 42558.345 | D24: - | E24: =$B$15 -> 42558.345
A25: 2 | B25: Monthly Payment | C25: =$B$15 -> 42558.345 | D25: - | E25: =$B$15 -> 42558.345
A26: 3 | B26: Monthly Payment | C26: =$B$15 -> 42558.345 | D26: - | E26: =$B$15 -> 42558.345
A27: 4 | B27: Monthly Payment | C27: =$B$15 -> 42558.345 | D27: - | E27: =$B$15 -> 42558.345
A28: 5 | B28: Monthly Payment | C28: =$B$15 -> 42558.345 | D28: - | E28: =$B$15 -> 42558.345
A29: 6 | B29: Monthly Payment | C29: =$B$15 -> 42558.345 | D29: - | E29: =$B$15 -> 42558.345
A30: 7 | B30: Monthly Payment | C30: =$B$15 -> 42558.345 | D30: - | E30: =$B$15 -> 42558.345
A31: 8 | B31: Monthly Payment | C31: =$B$15 -> 42558.345 | D31: - | E31: =$B$15 -> 42558.345
A32: 9 | C32: =$B$15 -> 42558.345 | D32: - | E32: =$B$15 -> 42558.345
A33: 10 | B33: Monthly Payment | C33: =$B$15 -> 42558.345 | D33: - | E33: =$B$15 -> 42558.345
A34: 11 | B34: Monthly Payment | C34: =$B$15 -> 42558.345 | D34: - | E34: =$B$15 -> 42558.345
A35: 12 | B35: Monthly Payment | C35: =$B$15 -> 42558.345 | D35: - | E35: =$B$15 -> 42558.345
A36: 13 | B36: Monthly Payment | C36: =$B$15 -> 42558.345 | D36: - | E36: =$B$15 -> 42558.345
A37: 14 | B37: Monthly Payment | C37: =$B$15 -> 42558.345 | D37: - | E37: =$B$15 -> 42558.345
A38: 15 | B38: Monthly Payment | C38: =$B$15 -> 42558.345 | D38: - | E38: =$B$15 -> 42558.345
A39: 16 | B39: Monthly Payment | C39: =$B$15 -> 42558.345 | D39: - | E39: =$B$15 -> 42558.345
A40: 17 | B40: Monthly Payment | C40: =$B$15 -> 42558.345 | D40: - | E40: =$B$15 -> 42558.345
A41: 18 | B41: Monthly Payment | C41: =$B$15 -> 42558.345 | D41: - | E41: =$B$15 -> 42558.345
A42: 19 | B42: Monthly Payment | C42: =$B$15 -> 42558.345 | D42: - | E42: =$B$15 -> 42558.345
A43: 20 | B43: Monthly Payment | C43: =$B$15 -> 42558.345 | D43: - | E43: =$B$15 -> 42558.345
A44: 21 | B44: Monthly Payment | C44: =$B$15 -> 42558.345 | D44: - | E44: =$B$15 -> 42558.345
...

Sheet Q2 Scenario & D-Bond
A1: Q2: Adverse Scenario – South Plains Mall Anchor Default & D-Bond Expected Cash Flows
A3: SCENARIO: DUAL ANCHOR NON-RENEWAL — SOUTH PLAINS MALL
A4: Scenario: Dillard's (25.2% NRA, lease exp Jan 2012) and JC Penney (21.4% NRA, lease exp Jul 2012) both fail to renew. Combined 46.6% NRA loss triggers co-tenancy clauses, collapsing inline tenant rents. Property value falls below loan balance → borrower defaults strategically (non-recourse loan). Default assumed at Month 30 (~2.5 yrs, when 2012 leases expire and distress is confirmed).
A5: Probability: 15% (assumed) — consistent with 2010 retail climate: Mervyn's already dark at the mall, Dillard's rated B3/B-, JC Penney rated Ba1/BB.
A7: SOUTH PLAINS MALL — LOAN FACTS (Exhibit 8) | D7: STRESS ASSUMPTIONS
A8: Loan Balance ($) | B8: 77700000 | D8: Dillard's NRA (sf) | E8: 257569 | F8: Exhibit 8: 25.2% of NRA
A9: Loan Rate (annual) | B9: 0.0427 | D9: Dillard's Rent PSF ($) | E9: 2.15 | F9: Exhibit 8: underwritten
A10: Amortization (months) | B10: 360 | D10: JC Penney NRA (sf) | E10: 218518 | F10: Exhibit 8: 21.4% of NRA
A11: Loan Term (months) | B11: 60 | D11: JC Penney Rent PSF ($) | E11: 1.85 | F11: Exhibit 8: underwritten
A12: Current NOI ($) | B12: 13015058 | D12: Co-tenancy Loss (%) | E12: 0.5 | F12: Conservative: 50% of remaining NOI lost
A13: Current DSCR | B13: 2.83 | D13: Stressed Cap Rate | E13: 0.1 | F13: Distressed mall; up from ~8.2% implied
A14: Appraised Value ($) | B14: 158000000 | D14: P(Default) | E14: 0.15
A15: Underwritten LTV | B15: 0.492 | D15: Default Month | E15: 30 | F15: ~Month lease crisis confirmed
A21: STRESS CALCULATIONS (Derived) | D21: POOL & D-BOND LOSS ALLOCATION
A22: Monthly Pmt – SPM Loan ($) | B22: =PMT(B9/12,B10,-B8) -> 383147.6 | D22: Pool & D-Bond Facts (Exhibit 7) | F22: Value
A23: Annual Debt Service ($) | B23: =B22*12 -> 4597771.2 | D23: Total Pool Balance ($) | F23: 309700000
A24: Dillard's Rent Lost ($) | B24: =E8*E9 -> 553773.35 | D24: D-Bond Face Value ($) | F24: 29434000
A25: JC Penney Rent Lost ($) | B25: =E10*E11 -> 404258.3 | D25: D-Bond Subordination | F25: 0
A26: Total Anchor Rent Lost ($) | B26: =B24+B25 -> 958031.65 | D26: D-Bond Coupon (pass-through) | F26: 0.0466349
A27: Co-tenancy NOI Lost ($) | B27: =(B12-B26)*E12 -> 6028513.2 | D27: Loan Term (months) | F27: 60
A28: Stressed NOI ($) | B28: =B12-B26-B27 -> 6028513.2 | D28: Pool Loss ($) | F28: =B34 -> 14044194
A29: Stressed DSCR | B29: =B28/B23 -> 1.3111816 | D29: Pool Loss (% of pool) | F29: =F28/F23 -> 0.045347735
A30: Stressed Property Value ($) | B30: =B28/E13 -> 60285132 | D30: D-Bond Monthly Coupon ($) | F30: =F24*F26/12 -> 114387.64
A31: Loan Bal at Default Month ($) | B31: =ABS(FV(B9/12,E15,-B22,B8)) -> 74329325 | D31: D-Bond Loss ($) | F31: =MIN(F28,F24) -> 14044194
A32: Recovery Amount ($) | B32: =MIN(B30,B31) -> 60285132 | D32: D-Bond Recovery ($) | F32: =F24-F31 -> 15389806
A33: Recovery Rate | B33: =B32/B31 -> 0.81105447 | D33: D-Bond Recovery Rate | F33: =F32/F24 -> 0.52285814
A34: Loss on SPM Loan ($) | B34: =B31-B32 -> 14044194
A36: D-BOND MONTHLY CASH FLOW TABLE
A37: Month | B37: Description | C37: Scen A: No Default (85%) CF ($) | D37: Scen B: Default Month 30 (15%) CF ($) | E37: Expected CF ($) = 0.85×A + 0.15×B | F37: Cumulative ECF ($) | G37: Notes
A38: 0 | B38: Initial Outlay | C38: -29434000 | D38: -29434000 | E38: -29434000 | F38: -29434000 | G38: Buy D-bond at par
A39: 1 | B39: Monthly Coupon | C39: =$F$30 -> 114387.64 | D39: =$F$30 -> 114387.64 | E39: =0.85*C39+0.15*D39 -> 114387.64 | F39: =F38+E39 -> -29319612
A40: 2 | B40: Monthly Coupon | C40: =$F$30 -> 114387.64 | D40: =$F$30 -> 114387.64 | E40: =0.85*C40+0.15*D40 -> 114387.64 | F40: =F39+E40 -> -29205225
A41: 3 | B41: Monthly Coupon | C41: =$F$30 -> 114387.64 | D41: =$F$30 -> 114387.64 | E41: =0.85*C41+0.15*D41 -> 114387.64 | F41: =F40+E41 -> -29090837
A42: 4 | B42: Monthly Coupon | C42: =$F$30 -> 114387.64 | D42: =$F$30 -> 114387.64 | E42: =0.85*C42+0.15*D42 -> 114387.64 | F42: =F41+E42 -> -28976449
A43: 5 | B43: Monthly Coupon | C43: =$F$30 -> 114387.64 | D43: =$F$30 -> 114387.64 | E43: =0.85*C43+0.15*D43 -> 114387.64 | F43: =F42+E43 -> -28862062
A44: 6 | B44: Monthly Coupon | C44: =$F$30 -> 114387.64 | D44: =$F$30 -> 114387.64 | E44: =0.85*C44+0.15*D44 -> 114387.64 | F44: =F43+E44 -> -28747674
A45: 7 | B45: Monthly Coupon | C45: =$F$30 -> 114387.64 | D45: =$F$30 -> 114387.64 | E45: =0.85*C45+0.15*D45 -> 114387.64 | F45: =F44+E45 -> -28633287
A46: 8 | B46: Monthly Coupon | C46: =$F$30 -> 114387.64 | D46: =$F$30 -> 114387.64 | E46: =0.85*C46+0.15*D46 -> 114387.64 | F46: =F45+E46 -> -28518899
A47: 9 | B47: Monthly Coupon | C47: =$F$30 -> 114387.64 | D47: =$F$30 -> 114387.64 | E47: =0.85*C47+0.15*D47 -> 114387.64 | F47: =F46+E47 -> -28404511
A48: 10 | B48: Monthly Coupon | C48: =$F$30 -> 114387.64 | D48: =$F$30 -> 114387.64 | E48: =0.85*C48+0.15*D48 -> 114387.64 | F48: =F47+E48 -> -28290124
...

Sheet Q3 D-Bond Pricing
A1: Q3: Required Return on D-Bond & Break-Even Purchase Price
A3: REQUIRED RETURN BUILD-UP | E3: Justification
A4: Baa Corporate Yield | B4: 0.064 | E4: Exhibit 14: Baa bonds yield 6.40%. D-bond rated Baa3/BBB- — this is the floor.
A5: Liquidity Premium | B5: 0.005 | E5: Rule 144A offering = not publicly registered, restricted resale. Typical illiquidity add-on 50bps.
A6: Concentration Premium | B6: 0.0075 | E6: Only 6 loans in pool vs hundreds in pre-crisis CMBS. Single-loan event risk is high. 75bps.
A7: Required Return on D-Bond | B7: =B4+B5+B6 -> 0.0765 | E7: Sum of above components.
A9: Direct Lending Expected Return (Q1) | B9: ='Q1 Direct Lending'!B88 -> 0.07124031 | E9: From Q1 — must beat direct lending to justify D-bond investment
A10: HURDLE RATE (max of above) | B10: =MAX(B7,B9) -> 0.0765 | E10: D-bond must at minimum match direct lending expected return
A12: Key difference from friend: Required return is built up from fundamentals (Baa base + liquidity + concentration premia) rather than simply copying Q1's direct lending return. The hurdle is then the MAX of these two — ensuring the D-bond beats both the market-implied rate for its risk level AND the direct lending alternative.
A14: BREAK-EVEN PRICE CALCULATION
A16: D-Bond Face Value ($) | B16: ='Q2 Scenario & D-Bond'!F24 -> 29434000
A17: Hurdle Rate (annual) | B17: =B10 -> 0.0765
A18: Hurdle Rate (monthly) | B18: =(1+B17)^(1/12)-1 -> 0.0061618262
A19: PV of Expected CFs (months 1–60) ($) | B19: =SUMPRODUCT('Q2 Scenario & D-Bond'!E39:E98,1/(1+B18)^ROW(INDIRECT("1:60"))) -> 24559121
A20: Break-Even Price ($) | B20: =B19 -> 24559121
A21: Break-Even Price (% of par) | B21: =B20/B16 -> 0.83437933
A22: Discount to Par | B22: =1-B21 -> 0.16562067
A24: UPL INVESTMENT OF $5.8M
A25: UPL Investment ($) | B25: 5800000
A26: Face Value Acquired at Break-Even Price ($) | B26: =B25/B21 -> 6951274.8
A27: Face Value at Par (for comparison) | B27: =B25 -> 5800000
A28: Extra Face Value from Discount ($) | B28: =B26-B27 -> 1151274.8
A30: Interpretation: By purchasing the D-bond at the break-even price (~83.4 cents on the dollar), UPL acquires ~$6.95M of face value for $5.8M. The discount compensates for: (1) the 15% probability of partial loss in our scenario, (2) zero subordination below the D-bond,
A32: D-BOND MONTHLY CASH FLOW TABLE AT BREAK-EVEN PRICE
A33: Month | B33: Description | C33: Scen A: No Default (85%) CF ($) | D33: Scen B: Default Month 30 (15%) CF ($) | E33: Expected CF ($) | F33: Cumulative ECF ($) | G33: Notes
A34: 0 | B34: Buy D-Bond at Break-Even Price | C34: =-B20 -> -24559121 | D34: =-B20 -> -24559121 | E34: =-B20 -> -24559121 | F34: =-B20 -> -24559121 | G34: Outlay = face × break-even price
A35: 1 | B35: Monthly Coupon | C35: ='Q2 Scenario & D-Bond'!C39 -> 114387.64 | D35: ='Q2 Scenario & D-Bond'!D39 -> 114387.64 | E35: =0.85*C35+0.15*D35 -> 114387.64 | F35: =F34+E35 -> -24444733
A36: 2 | B36: Monthly Coupon | C36: ='Q2 Scenario & D-Bond'!C40 -> 114387.64 | D36: ='Q2 Scenario & D-Bond'!D40 -> 114387.64 | E36: =0.85*C36+0.15*D36 -> 114387.64 | F36: =F35+E36 -> -24330346
A37: 3 | B37: Monthly Coupon | C37: ='Q2 Scenario & D-Bond'!C41 -> 114387.64 | D37: ='Q2 Scenario & D-Bond'!D41 -> 114387.64 | E37: =0.85*C37+0.15*D37 -> 114387.64 | F37: =F36+E37 -> -24215958
A38: 4 | B38: Monthly Coupon | C38: ='Q2 Scenario & D-Bond'!C42 -> 114387.64 | D38: ='Q2 Scenario & D-Bond'!D42 -> 114387.64 | E38: =0.85*C38+0.15*D38 -> 114387.64 | F38: =F37+E38 -> -24101571
A39: 5 | B39: Monthly Coupon | C39: ='Q2 Scenario & D-Bond'!C43 -> 114387.64 | D39: ='Q2 Scenario & D-Bond'!D43 -> 114387.64 | E39: =0.85*C39+0.15*D39 -> 114387.64 | F39: =F38+E39 -> -23987183
A40: 6 | B40: Monthly Coupon | C40: ='Q2 Scenario & D-Bond'!C44 -> 114387.64 | D40: ='Q2 Scenario & D-Bond'!D44 -> 114387.64 | E40: =0.85*C40+0.15*D40 -> 114387.64 | F40: =F39+E40 -> -23872795
A41: 7 | B41: Monthly Coupon | C41: ='Q2 Scenario & D-Bond'!C45 -> 114387.64 | D41: ='Q2 Scenario & D-Bond'!D45 -> 114387.64 | E41: =0.85*C41+0.15*D41 -> 114387.64 | F41: =F40+E41 -> -23758408
A42: 8 | B42: Monthly Coupon | C42: ='Q2 Scenario & D-Bond'!C46 -> 114387.64 | D42: ='Q2 Scenario & D-Bond'!D46 -> 114387.64 | E42: =0.85*C42+0.15*D42 -> 114387.64 | F42: =F41+E42 -> -23644020
A43: 9 | B43: Monthly Coupon | C43: ='Q2 Scenario & D-Bond'!C47 -> 114387.64 | D43: ='Q2 Scenario & D-Bond'!D47 -> 114387.64 | E43: =0.85*C43+0.15*D43 -> 114387.64 | F43: =F42+E43 -> -23529632
A44: 10 | B44: Monthly Coupon | C44: ='Q2 Scenario & D-Bond'!C48 -> 114387.64 | D44: ='Q2 Scenario & D-Bond'!D48 -> 114387.64 | E44: =0.85*C44+0.15*D44 -> 114387.64 | F44: =F43+E44 -> -23415245
A45: 11 | B45: Monthly Coupon | C45: ='Q2 Scenario & D-Bond'!C49 -> 114387.64 | D45: ='Q2 Scenario & D-Bond'!D49 -> 114387.64 | E45: =0.85*C45+0.15*D45 -> 114387.64 | F45: =F44+E45 -> -23300857
A46: 12 | B46: Monthly Coupon | C46: ='Q2 Scenario & D-Bond'!C50 -> 114387.64 | D46: ='Q2 Scenario & D-Bond'!D50 -> 114387.64 | E46: =0.85*C46+0.15*D46 -> 114387.64 | F46: =F45+E46 -> -23186469
... A63: 29 | B63: Monthly Coupon | C63: ='Q2 Scenario & D-Bond'!C67 -> 114387.64 | D63: ='Q2 Scenario & D-Bond'!D67 -> 114387.64 | E63: =0.85*C63+0.15*D63 -> 114387.64 | F63: =F62+E63 -> -21241880
A64: 30 | B64: Default Month — Last Coupon + Recovery (Scen B) | C64: ='Q2 Scenario & D-Bond'!C68 -> 114387.64 | D64: ='Q2 Scenario & D-Bond'!D68 -> 15504194 | E64: =0.85*C64+0.15*D64 -> 2422858.6 | F64: =F63+E64 -> -18819021 | G64: Recovery received; Scen B ends
...
